Workbook

Sheet MASTER
A1: DASHBOARD CONSOLIDADO - GRUPO DELGA 2026
A2: Atualizado: | B2: 13/01/2026 | D2: Semana:
A4: VISÃO GERAL - BIG NUMBERS
A5: META ANUAL | C5: REALIZADO YTD | E5: % ATINGIMENTO | G5: GAP | I5: PROJETOS ATIVOS | K5: KAIZENS
A6: R$ 50,32 Mi | C6: R$ 0 | E6: 0% | G6: R$ 50,32 Mi | I6: 0 | K6: 0
A8: SAVING POR FONTE
A9: FONTE | B9: META | C9: REALIZADO | D9: % ATING. | E9: GAP | F9: STATUS
A10: Diadema | B10: 6947000 | C10: 0 | D10: =IF(B10=0,0,C10/B10) -> 0 | E10: =B10-C10 -> 6947000
A11: Ferraz | B11: 13367000 | C11: 0 | D11: =IF(B11=0,0,C11/B11) -> 0 | E11: =B11-C11 -> 13367000
A12: São Leopoldo | B12: 2100000 | C12: 0 | D12: =IF(B12=0,0,C12/B12) -> 0 | E12: =B12-C12 -> 2100000
A13: Jarinu | B13: 5356000 | C13: 0 | D13: =IF(B13=0,0,C13/B13) -> 0 | E13: =B13-C13 -> 5356000
A14: Anchieta | B14: 3841000 | C14: 0 | D14: =IF(B14=0,0,C14/B14) -> 0 | E14: =B14-C14 -> 3841000
A15: Compras | B15: 7000000 | C15: 0 | D15: =IF(B15=0,0,C15/B15) -> 0 | E15: =B15-C15 -> 7000000
A16: Vendas | B16: 10000000 | C16: 0 | D16: =IF(B16=0,0,C16/B16) -> 0 | E16: =B16-C16 -> 10000000
A17: Corporativo | B17: 1709000
A18: TOTAL | B18: =SUM(B10:B16) -> 48611000 | C18: =SUM(C10:C16) -> 0 | D18: =IF(B18=0,0,C18/B18) -> 0 | E18: =B18-C18 -> 48611000
A20: KPIs OPERACIONAIS - COMPARATIVO UNIDADES
A21: KPI | B21: META | C21: DIADEMA | D21: FERRAZ | E21: SÃO LEOPOLDO | F21: JARINU | G21: ANCHIETA | H21: MÉDIA | I21: STATUS
H22: =AVERAGE(C22:G22) -> #DIV/0!
H23: =AVERAGE(C23:G23) -> #DIV/0!
H24: =AVERAGE(C24:G24) -> #DIV/0!
H25: =AVERAGE(C25:G25) -> #DIV/0!
H26: =AVERAGE(C26:G26) -> #DIV/0!
H27: =AVERAGE(C27:G27) -> #DIV/0!
H28: =AVERAGE(C28:G28) -> #DIV/0!
H29: =AVERAGE(C29:G29) -> #DIV/0!
H30: =AVERAGE(C30:G30) -> #DIV/0!
H31: =AVERAGE(C31:G31) -> #DIV/0!
H32: =AVERAGE(C32:G32) -> #DIV/0!
H33: =AVERAGE(C33:G33) -> #DIV/0!
... H37: =AVERAGE(C37:G37) -> #DIV/0!
A40: DESTAQUES DA SEMANA | H40: RISCOS E AÇÕES
A41: 1. | H41: 1.
A42: 2. | H42: 2.
A43: 3. | H43: 3.
A44: 4. | H44: 4.
A45: 5. | H45: 5.

Sheet 5 Unidades  +
D3: DASHBOARD EXECUTIVO - GRUPO DELGA
D4: Gestão Estratégica de Projetos e Redução de Custos | Grupo Delga | 2026
D6: META DO GRUPO 2026 | E6: RETORNO PREVISTO (Anual) | F6: Retorno Validado (Anual) | G6: PREVISTO 2026 | H6: 💰 RETORNO VALIDADO 2026 | J6: 💰 RETORNO REAL 2026 | K6: Extra DRE (Até o momento) | L6: % ATINGIMENTO DA META | N6: INICIATIVAS | P6: Top 03 Projetos (Maior Retorno REAL até o momento) | V6: Kaizen - Capital de Giro | W6: redução de estoque, melhora o caixa mas não o DRE de forma tangível
D7: =Diadema!A5+Ferraz!A5+'São Leopoldo'!A5+Jarinu!A5+Anchieta!A5+Corporativo!A5+'Compras '!A5+Vendas!A5+'Diretoria Financeira'!A5+'Head Qualidade&Dir. Industrial'!A5 -> 50320000 | E7: =Diadema!B5+Jarinu!B5+Ferraz!B5+Anchieta!B5+'São Leopoldo'!B5+'Compras '!C5+Vendas!C5+Corporativo!C5 -> 54030314 | F7: =Diadema!C5+Jarinu!C5+Ferraz!C5+Anchieta!C5+'São Leopoldo'!C5+'Compras '!D5 -> 24988665 | G7: =Diadema!D5+Jarinu!D5+Ferraz!D5+Anchieta!D5+'São Leopoldo'!D5+'Compras '!E5+Vendas!E5 -> 33811407 | H7: =Diadema!E5+Jarinu!E5+Ferraz!E5+Anchieta!E5+'São Leopoldo'!E5+'Compras '!G5+Vendas!G5 -> 15697315 | J7: =Diadema!G5+Ferraz!G5+Jarinu!G5+'São Leopoldo'!G5+Anchieta!G5+'Compras '!I5+Vendas!I5+Corporativo!G5 -> 5623569.8 | K7: =Diadema!I5+Ferraz!I5+Jarinu!I5+'São Leopoldo'!I5+Anchieta!I5+Vendas!I7 -> 3579261.8 | L7: =J7/D7 -> 0.11175616 | N7: =E21 -> 216 | P7: =K56 -> 1546534.7 | Q7: =F56 -> Negociação de preços materiais carcaça Dana | S7: =E56 -> Compras | V7: Kaizen - Ganho Recorrente | W7: impacto direto e tangível no DRE
P8: =J57 -> 520985.23 | Q8: =F57 -> 07- Reestruturação | S8: =E57 -> São leopoldo | V8: Kaizen - Custo Evitado | W8: Ganho real, mas não reflete diretamente como redução no DRE
P9: =K58 -> 412708.21 | Q9: =F58 -> Projeto DANA - Mudança de CH para BQ | S9: =E58 -> Compras
D11: 📊 SAVING ESPECULADO POR PILAR | I11: 📋 STATUS DAS INICIATIVAS | L11: 🏭 INDICADORES OPERACIONAIS | P11: MATRIZ SPD 5 unidades
D12: Pilar | E12: Qtd. | F12: Saving (R$) | G12: Saving Validado 2026 | H12: Até o Momento | I12: Status | J12: Qtd. | K12: R$ Previsto | L12: Aderência SPD: Unidade | M12: Aderência SPD: Auditado | N12: Análise de Margem | P12: Tipo | Q12: Unidade | R12: Auditado | S12: Meta
D13: Kaizen - Capital de Giro | E13: =Diadema!B8+Ferraz!B8+Jarinu!B8+'São Leopoldo'!B8+Anchieta!B8 -> 1 | F13: =Diadema!C8+Ferraz!C8+Jarinu!C8+'São Leopoldo'!C8+Anchieta!C8 -> 195011 | G13: =Diadema!D8+Ferraz!D8+Jarinu!D8+'São Leopoldo'!D8+Anchieta!D8 -> 0 | H13: =Diadema!E8+Ferraz!E8+Jarinu!E8+'São Leopoldo'!E8+Anchieta!E8 -> 195000 | I13: ✓ Concluído | J13: =Diadema!G8+Ferraz!G8+Jarinu!G8+'São Leopoldo'!G8+Anchieta!G8+'Compras '!H9+Vendas!M11+Vendas!P11 -> 107 | K13: =SUM(Diadema!H8,Ferraz!H8,'São Leopoldo'!H8,Jarinu!H8,Anchieta!H8,Corporativo!I9,'Compras '!I9,Vendas!N11,'Diretoria Financeira'!I9,'Head Qualidade&Dir. Industrial'!I9) -> 19638792 | P13: Produtividade e Controle | Q13: =SUM(Diadema!L219,Anchieta!L132,Ferraz!L174,Jarinu!L174,'São Leopoldo'!L134)/5 -> 0.95 | R13: =SUM(Diadema!M219,Anchieta!M132,Ferraz!M174,Jarinu!M174,'São Leopoldo'!M134)/5 -> 0.9 | S13: 1
D14: Kaizen - Ganho Recorrente | E14: =Diadema!B9+Ferraz!B9+Jarinu!B9+'São Leopoldo'!B9+Anchieta!B9 -> 30 | F14: =Diadema!C9+Ferraz!C9+Jarinu!C9+'São Leopoldo'!C9+Anchieta!C9 -> 3114920.1 | G14: =Diadema!D9+Ferraz!D9+Jarinu!D9+'São Leopoldo'!D9+Anchieta!D9 -> 2409427.6 | H14: =Diadema!E9+Ferraz!E9+Jarinu!E9+'São Leopoldo'!E9+Anchieta!E9 -> 1266744.9 | I14: ⏳ Em Execução | J14: =SUM(Diadema!G9,Ferraz!G9,'São Leopoldo'!G9,Jarinu!G9,Anchieta!G9,Corporativo!H10,'Compras '!H10,Vendas!M12,'Diretoria Financeira'!H10,'Head Qualidade&Dir. Industrial'!H10,Vendas!P12) -> 82 | K14: =SUM(Diadema!H9,Ferraz!H9,'São Leopoldo'!H9,Jarinu!H9,Anchieta!H9,Corporativo!I10,'Compras '!I10,Vendas!N12,'Diretoria Financeira'!I10,'Head Qualidade&Dir. Industrial'!I10) -> 18061986 | L14: =AVERAGE(Diadema!I9,Ferraz!I9,'São Leopoldo'!I9:I10,Jarinu!I9,Anchieta!I9) -> 0.98333333 | M14: =AVERAGE(Diadema!J9,Ferraz!J9,'São Leopoldo'!J9:J10,Jarinu!J9,Anchieta!J9) -> 0.94166667 | N14: =AVERAGE(Diadema!K9,Ferraz!K9,'São Leopoldo'!K9,Jarinu!K9,Anchieta!K9) -> 0.26601787 | P14: Documentos e Registro | Q14: =SUM(Diadema!L220,Anchieta!L133,Ferraz!L175,Jarinu!L175,'São Leopoldo'!L135)/5 -> 0.95 | R14: =SUM(Diadema!M220,Anchieta!M133,Ferraz!M175,Jarinu!M175,'São Leopoldo'!M135)/5 -> 0.85 | S14: 1
D15: Kaizen - Custo Evitado | E15: =Diadema!B10+Ferraz!B10+Jarinu!B10+'São Leopoldo'!B10+Anchieta!B10 -> 21 | F15: =Diadema!C10+Ferraz!C10+Jarinu!C10+'São Leopoldo'!C10+Anchieta!C10 -> 6718186.2 | G15: =Diadema!D10+Ferraz!D10+Jarinu!D10+'São Leopoldo'!D10+Anchieta!D10 -> 0 | H15: =Diadema!E10+Ferraz!E10+Jarinu!E10+'São Leopoldo'!E10+Anchieta!E10 -> 3373042 | I15: 📝 Não iniciado | J15: =SUM(Diadema!G10,Ferraz!G10,'São Leopoldo'!G10,Jarinu!G10,Anchieta!G10,Corporativo!H11,'Compras '!H11,Vendas!M13,'Diretoria Financeira'!H11,'Head Qualidade&Dir. Industrial'!H11,Vendas!P13) -> 17 | K15: =SUM(Diadema!H10,Ferraz!H10,'São Leopoldo'!H10,Jarinu!H10,Anchieta!H10,Corporativo!I11,'Compras '!I11,Vendas!N13,'Diretoria Financeira'!I11,'Head Qualidade&Dir. Industrial'!I11) -> 1397973 | P15: Manutenção do Processo | Q15: =SUM(Diadema!L221,Anchieta!L134,Ferraz!L176,Jarinu!L176,'São Leopoldo'!L136)/5 -> 0.98333333 | R15: =SUM(Diadema!M221,Anchieta!M134,Ferraz!M176,Jarinu!M176,'São Leopoldo'!M136)/5 -> 0.96666667 | S15: 1
D16: Kaizen | E16: =Ferraz!B11+Jarinu!B11+'São Leopoldo'!B11+Anchieta!B11+'Compras '!B9+Vendas!B11+Corporativo!B9 -> 21 | F16: =Ferraz!C11+Jarinu!C11+'São Leopoldo'!C11+Anchieta!C11+'Compras '!C9+Vendas!C11 -> 3087374.2 | G16: =Ferraz!D11+Jarinu!D11+'São Leopoldo'!D11+Anchieta!D11+'Compras '!D9 -> 2082433.4 | H16: =Ferraz!E11+Jarinu!E11+'São Leopoldo'!E11+Anchieta!E11+'Compras '!E9+Vendas!E11 -> 970520.54 | P16: Análise dos Dados | Q16: =SUM(Diadema!L222,Anchieta!L135,Ferraz!L177,Jarinu!L177,'São Leopoldo'!L137)/5 -> 1 | R16: =SUM(Diadema!M222,Anchieta!M135,Ferraz!M177,Jarinu!M177,'São Leopoldo'!M137)/5 -> 1 | S16: 1
D17: Redução de Custo | E17: =Diadema!B11+Ferraz!B12+Jarinu!B12+'São Leopoldo'!B12+Anchieta!B12+'Compras '!B10+Vendas!B12+Corporativo!B10 -> 85 | F17: =Diadema!C11+Ferraz!C12+Jarinu!C12+'São Leopoldo'!C12+Anchieta!C12+'Compras '!C10+Vendas!C12 -> 23699907 | G17: =Diadema!D11+Ferraz!D12+Jarinu!D12+'São Leopoldo'!D12+Anchieta!D12+'Compras '!D10+Vendas!D12+Corporativo!D10 -> 6769731.5 | H17: =Diadema!E11+Ferraz!E12+Jarinu!E12+'São Leopoldo'!E12+Anchieta!E12+'Compras '!E10+Vendas!E12 -> 2600128.3
D18: Você Resolve | E18: =Diadema!B12+Ferraz!B13+Jarinu!B13+'São Leopoldo'!B13+Anchieta!B13+'Compras '!B12+Vendas!B13+Corporativo!B11 -> 1 | F18: =Diadema!C12+Ferraz!C13+Jarinu!C13+'São Leopoldo'!C13+Anchieta!C13+'Compras '!C11+Vendas!C13 -> 1000000 | G18: =Diadema!D12+Ferraz!D13+Jarinu!D13+'São Leopoldo'!D13+Anchieta!D13+'Compras '!D11+Vendas!D13 -> 240000 | H18: =Diadema!E12+Ferraz!E13+Jarinu!E13+'São Leopoldo'!E13+Anchieta!E13+'Compras '!E11+Vendas!E13 -> 0
D19: BSW | E19: =Diadema!B13+Ferraz!B14+Jarinu!B14+'São Leopoldo'!B14+Anchieta!B14+'Compras '!B12+Vendas!B14+Corporativo!B12 -> 57 | F19: =Diadema!C13+Ferraz!C14+Jarinu!C14+'São Leopoldo'!C14+Anchieta!C14+'Compras '!C12+Vendas!C14 -> 6558514.2 | G19: =Diadema!D13+Ferraz!D14+Jarinu!D14+'São Leopoldo'!D14+Anchieta!D14+'Compras '!D13 -> 4414449.3 | H19: =Diadema!E13+Ferraz!E14+Jarinu!E14+'São Leopoldo'!E14+Anchieta!E14+'Compras '!E12+Vendas!E14 -> 774956.23
D20: Estratégia Comercial | E20: =Vendas!B15 -> 1 | F20: =Vendas!C15 -> 9996000 | G20: =Vendas!D15 -> 0 | H20: =Vendas!E15 -> 0
D21: TOTAL | E21: =SUM(E13:E19) -> 216 | F21: =SUM(F13:F20) -> 54369913 | G21: =SUM(G13:G20) -> 15916042 | H21: =SUM(H13:H20) -> 9180392.1
D22: - | E22: Diadema | F22: Ferraz | G22: São Leopoldo | H22: Jarinu | I22: Anchieta | J22: Corporativo | K22: Compras | L22: Vendas
D23: META DA UNIDADE | E23: =Diadema!A5 -> 6947000 | F23: =Ferraz!A5 -> 13367000 | G23: ='São Leopoldo'!A5 -> 2100000 | H23: =Jarinu!A5 -> 5356000 | I23: =Anchieta!A5 -> 3841000 | J23: =Corporativo!A5 -> 1709000 | K23: ='Compras '!A5 -> 7000000 | L23: =Vendas!A5 -> 10000000 | M23: VA | N23: =Diadema!G15+Jarinu!G15+Ferraz!G15+'São Leopoldo'!G15+Anchieta!G15+'Compras '!P17 -> 8370195.8
D24: RETORNO PREVISTO | E24: =Diadema!C5 -> 4424279.6 | F24: =Ferraz!B5 -> 13813000 | G24: ='São Leopoldo'!B5 -> 2230520.7 | H24: =Jarinu!B5 -> 5582548 | I24: =Anchieta!B5 -> 1612623.6 | J24: =Corporativo!C5 -> 0 | K24: ='Compras '!C5 -> 15589000 | L24: =Vendas!C5 -> 10541563 | M24: GGF | N24: =Diadema!G16+Jarinu!G16+Ferraz!G16+'São Leopoldo'!G16+Anchieta!G16+'Compras '!P18 -> 4317459.2
D25: PREVISTO (Concluido) | E25: =Diadema!H8 -> 3446352.2 | F25: =Ferraz!H8 -> 3632600 | G25: ='São Leopoldo'!H8 -> 1422892.8 | H25: =Jarinu!H8 -> 1395112 | I25: =Anchieta!H8 -> 212144 | J25: =Corporativo!I9 -> 0 | K25: ='Compras '!I9 -> 9529691.1 | L25: =Vendas!N11 -> 0 | M25: MA | N25: =Diadema!G17+Jarinu!G17+Ferraz!G17+'São Leopoldo'!G17+Anchieta!G17+'Compras '!P19 -> 2303528.2
D26: 💰 RETORNO VALIDADO | E26: =Diadema!E5 -> 2877285.2 | F26: =Ferraz!E5 -> 2448486.8 | G26: ='São Leopoldo'!E5 -> 2196413.4 | H26: =Jarinu!E5 -> 2945612.6 | I26: =Anchieta!E5 -> 464467.83 | J26: =Corporativo!E5 -> 0 | K26: ='Compras '!G5 -> 4765049.3 | L26: =Vendas!G5 -> 0 | M26: Outros | N26: =Diadema!G18+Jarinu!G18+Ferraz!G18+'São Leopoldo'!G18+Anchieta!G18+'Compras '!P20 -> 706132
D27: 💰 RETORNO REAL | E27: =Diadema!G5 -> 1008796 | F27: =Ferraz!G5 -> 1367465.6 | G27: ='São Leopoldo'!G5 -> 1158700.7 | H27: =Jarinu!G5 -> 463507.45 | I27: =Anchieta!G5 -> 331443.95 | J27: =Corporativo!G5 -> 0 | K27: ='Compras '!I5 -> 1282436.3 | L27: =Vendas!G5 -> 0
D28: % ATINGIMENTO DA META | E28: =Diadema!J5 -> 0.14521318 | F28: =Ferraz!J5 -> 0.10230161 | G28: ='São Leopoldo'!J5 -> 0.55176223 | H28: =Jarinu!J5 -> 0.086539852 | I28: =Anchieta!J5 -> 0.086291056 | J28: =Corporativo!J5 -> 0 | K28: ='Compras '!L5 -> 0.18320519 | L28: =Vendas!J5 -> 0
D29: Extra DRE | E29: =Diadema!I5 -> 137181.16 | F29: =Ferraz!I5 -> 2135000 | G29: ='São Leopoldo'!I5 -> 120860.88 | H29: =Jarinu!I5 -> 1009000 | I29: =Anchieta!I5 -> 166000 | J29: =Diadema!N5 -> 0 | L29: =Vendas!E7 -> 137632.63
D30: INICIATIVAS | E30: =Diadema!L5 -> 57 | F30: =Ferraz!L5 -> 21 | G30: ='São Leopoldo'!L5 -> 18 | H30: =Jarinu!L5 -> 37 | I30: =Anchieta!L5 -> 16 | J30: =Corporativo!M5 -> 0 | K30: ='Compras '!O5 -> 50 | L30: =Vendas!M5 -> 0
D31: Status SPD: Unidade | E31: =Diadema!I9 -> 1 | F31: =Ferraz!I9 -> 1 | G31: ='São Leopoldo'!I9 -> 1 | H31: =Jarinu!I9 -> 0.91666667 | I31: =Anchieta!I9 -> 1
D32: Status SPD: Auditado | E32: =Diadema!J9 -> 0.91666667 | F32: =Ferraz!J9 -> 0.95833333 | G32: ='São Leopoldo'!J9 -> 0.95833333 | H32: =Jarinu!J9 -> 0.91666667 | I32: =Anchieta!J9 -> 0.95833333
D33: Análise de Margem | E33: =N14 -> 0.26601787 | F33: =Ferraz!K9 -> 0.20833333 | G33: ='São Leopoldo'!K9 -> 0.1025641 | H33: =Jarinu!K9 -> 0.43333333 | I33: =Anchieta!K9 -> 0.33333333
F54: ,
D55: Posição | E55: Unidade / Departamento | F55: Nome do projeto /Inicio do Saving | H55: Status | I55: Status de Custos | J55: Previsto em 2026 | K55: Valor Previsto até o Momento | L55: Valor Real até o Momento | M55: Delta | W55: 46023 | X55: 46054 | Y55: 46082 | Z55: 46113 | AA55: 46143 | AB55: 46174 | AC55: 46204 | AD55: 46235 | AE55: 46266 | AF55: 46296 | AG55: 46327 | AH55: 46357 | AI55: total
D56: 1 | E56: =_xlfn.XLOOKUP(F56,Pareto!S:S,Pareto!T:T) -> Compras | F56: =_xlfn.XLOOKUP(K56,Pareto!V:V,Pareto!S:S) -> Negociação de preços materiais carcaça Dana | H56: =_xlfn.XLOOKUP(F56,Pareto!S:S,Pareto!X:X) -> ✓ Concluído | I56: =_xlfn.XLOOKUP('5 Unidades +'!F56,Pareto!S:S,Pareto!Z:Z) -> OK | J56: =_xlfn.XLOOKUP(F56,Pareto!S:S,Pareto!U:U) -> 2651202.3 | K56: =IFERROR(LARGE(Pareto!V:V,'5 Unidades +'!D56),"0") -> 1546534.7 | L56: =_xlfn.XLOOKUP(F56,Pareto!S:S,Pareto!W:W) -> 1154706.2 | M56: =IF(L56="",-K56,L56-K56) -> -391828.45 | V56: Previsto | W56: =SUM(Diadema!T179,Ferraz!S147,'São Leopoldo'!S109,Jarinu!S147,Anchieta!S105,Corporativo!L75,'Compras '!P147,Vendas!L86,'Diretoria Financeira'!L71,'Head Qualidade&Dir. Industrial'!L71) -> 1727858.4 | X56: =SUM(Diadema!U179,Ferraz!T147,'São Leopoldo'!T109,Jarinu!T147,Anchieta!T105,Corporativo!M75,'Compras '!Q147,Vendas!M86,'Diretoria Financeira'!M71,'Head Qualidade&Dir. Industrial'!M71) -> 1401255.9 | Y56: =SUM(Diadema!V179,Ferraz!U147,'São Leopoldo'!U109,Jarinu!U147,Anchieta!U105,Corporativo!N75,'Compras '!R147,Vendas!N86,'Diretoria Financeira'!N71,'Head Qualidade&Dir. Industrial'!N71) -> 1847170.5 | Z56: =SUM(Diadema!W179,Ferraz!V147,'São Leopoldo'!V109,Jarinu!V147,Anchieta!V105,Corporativo!O75,'Compras '!S147,Vendas!O86,'Diretoria Financeira'!O71,'Head Qualidade&Dir. Industrial'!O71) -> 1930171.6 | AA56: =SUM(Diadema!X179,Ferraz!W147,'São Leopoldo'!W109,Jarinu!W147,Anchieta!W105,Corporativo!P75,'Compras '!T147,Vendas!P86,'Diretoria Financeira'!P71,'Head Qualidade&Dir. Industrial'!P71) -> 2108484.9 | AB56: =SUM(Diadema!Y179,Ferraz!X147,'São Leopoldo'!X109,Jarinu!X147,Anchieta!X105,Corporativo!Q75,'Compras '!U147,Vendas!Q86,'Diretoria Financeira'!Q71,'Head Qualidade&Dir. Industrial'!Q71) -> 2694845.5 | AC56: =SUM(Diadema!Z179,Ferraz!Y147,'São Leopoldo'!Y109,Jarinu!Y147,Anchieta!Y105,Corporativo!R75,'Compras '!V147,Vendas!R86,'Diretoria Financeira'!R71,'Head Qualidade&Dir. Industrial'!R71) -> 2949641.2 | AD56: =SUM(Diadema!AA179,Ferraz!Z147,'São Leopoldo'!Z109,Jarinu!Z147,Anchieta!Z105,Corporativo!S75,'Compras '!W147,Vendas!S86,'Diretoria Financeira'!S71,'Head Qualidade&Dir. Industrial'!S71) -> 3749259.2 | ... AH56: =SUM(Diadema!AE179,Ferraz!AD147,'São Leopoldo'!AD109,Jarinu!AD147,Anchieta!AD105,Corporativo!W75,'Compras '!AA147,Vendas!W86,'Diretoria Financeira'!W71,'Head Qualidade&Dir. Industrial'!W71) -> 7305948.1 | AI56: =SUM(W56:AH56) -> 40637373
D57: 2 | E57: =_xlfn.XLOOKUP(F57,Pareto!S:S,Pareto!T:T) -> São leopoldo | F57: =_xlfn.XLOOKUP(K57,Pareto!V:V,Pareto!S:S) -> 07- Reestruturação | H57: =_xlfn.XLOOKUP(F57,Pareto!S:S,Pareto!X:X) -> ✓ Concluído | I57: =_xlfn.XLOOKUP('5 Unidades +'!F57,Pareto!S:S,Pareto!Z:Z) -> OK | J57: =_xlfn.XLOOKUP(F57,Pareto!S:S,Pareto!U:U) -> 520985.23 | K57: =IFERROR(LARGE(Pareto!V:V,D57)," ") -> 868308.71 | L57: =_xlfn.XLOOKUP(F57,Pareto!S:S,Pareto!W:W) -> 933084 | M57: =IF(L57="",-K57,L57-K57) -> 64775.285 | V57: Real | W57: =Diadema!T180+Jarinu!S148+Ferraz!S148+Anchieta!S106+'São Leopoldo'!S110+'Compras '!P148+Vendas!L87+Corporativo!M74 -> 823549.22 | X57: =Diadema!U180+Jarinu!T148+Ferraz!T148+Anchieta!T106+'São Leopoldo'!T110+'Compras '!Q148+Vendas!M87+Corporativo!N74 -> 683834.99 | Y57: =Diadema!V180+Jarinu!U148+Ferraz!U148+Anchieta!U106+'São Leopoldo'!U110+'Compras '!R148+Vendas!N87+Corporativo!O74 -> 830718.25 | Z57: =Diadema!W180+Jarinu!V148+Ferraz!V148+Anchieta!V106+'São Leopoldo'!V110+'Compras '!S148+Vendas!O87+Corporativo!P74 -> 812633.96 | AA57: =Diadema!X180+Jarinu!W148+Ferraz!W148+Anchieta!W106+'São Leopoldo'!W110+'Compras '!T148+Vendas!P87+Corporativo!Q74 -> 997294.15 | AB57: =Diadema!Y180+Jarinu!X148+Ferraz!X148+Anchieta!X106+'São Leopoldo'!X110+'Compras '!U148+Vendas!Q87+Corporativo!R74 -> 1132843.2 | AC57: =Diadema!Z180+Jarinu!Y148+Ferraz!Y148+Anchieta!Y106+'São Leopoldo'!Y110+'Compras '!V148+Vendas!R87+Corporativo!S74 -> 325111.97 | AD57: =Diadema!AA180+Jarinu!Z148+Ferraz!Z148+Anchieta!Z106+'São Leopoldo'!Z110+'Compras '!W148+Vendas!S87+Corporativo!T74 -> 17584 | ... AH57: =Diadema!AE180+Jarinu!AD148+Ferraz!AD148+Anchieta!AD106+'São Leopoldo'!AD110+'Compras '!AA148+Vendas!W87+Corporativo!X74 -> 0 | AI57: =SUM(W57:AH57) -> 5623569.8
D58: 3 | E58: =_xlfn.XLOOKUP(F58,Pareto!S:S,Pareto!T:T) -> Compras | F58: =_xlfn.XLOOKUP(K58,Pareto!V:V,Pareto!S:S) -> Projeto DANA - Mudança de CH para BQ | H58: =_xlfn.XLOOKUP(F58,Pareto!S:S,Pareto!X:X) -> ✓ Concluído | I58: =_xlfn.XLOOKUP('5 Unidades +'!F58,Pareto!S:S,Pareto!Z:Z) -> OK | J58: =_xlfn.XLOOKUP(F58,Pareto!S:S,Pareto!U:U) -> 1444478.7 | K58: =IFERROR(LARGE(Pareto!V:V,D58)," ") -> 412708.21 | L58: =_xlfn.XLOOKUP(F58,Pareto!S:S,Pareto!W:W) | M58: =IF(L58="",-K58,L58-K58) -> -412708.21 | V58: Q. Projetos | W58: =Diadema!T181+Anchieta!S107+Ferraz!S149+Jarinu!S149+'São Leopoldo'!S111+Corporativo!L76+Vendas!L88+'Compras '!P149 -> #REF! | X58: =SUM(Diadema!U181,Ferraz!T149,'São Leopoldo'!T111,Jarinu!T149,Anchieta!T107,Corporativo!M77,'Compras '!Q149,Vendas!M88,'Diretoria Financeira'!M73) -> #REF! | Y58: =SUM(Diadema!V181,Ferraz!U149,'São Leopoldo'!U111,Jarinu!U149,Anchieta!U107,Corporativo!N77,'Compras '!R149,Vendas!N88,'Diretoria Financeira'!N73) -> #REF! | Z58: =SUM(Diadema!W181,Ferraz!V149,'São Leopoldo'!V111,Jarinu!V149,Anchieta!V107,Corporativo!O77,'Compras '!S149,Vendas!O88,'Diretoria Financeira'!O73) -> #REF! | AA58: =SUM(Diadema!X181,Ferraz!W149,'São Leopoldo'!W111,Jarinu!W149,Anchieta!W107,Corporativo!P77,'Compras '!T149,Vendas!P88,'Diretoria Financeira'!P73) -> #REF! | AB58: =SUM(Diadema!Y181,Ferraz!X149,'São Leopoldo'!X111,Jarinu!X149,Anchieta!X107,Corporativo!Q77,'Compras '!U149,Vendas!Q88,'Diretoria Financeira'!Q73) -> #REF! | AC58: =SUM(Diadema!Z181,Ferraz!Y149,'São Leopoldo'!Y111,Jarinu!Y149,Anchieta!Y107,Corporativo!R77,'Compras '!V149,Vendas!R88,'Diretoria Financeira'!R73) -> #REF! | AD58: =SUM(Diadema!AA181,Ferraz!Z149,'São Leopoldo'!Z111,Jarinu!Z149,Anchieta!Z107,Corporativo!S77,'Compras '!W149,Vendas!S88,'Diretoria Financeira'!S73) -> #REF! | AE58: =SUM(Diadema!AB181,Ferraz!AA149,'São Leopoldo'!AA111,Jarinu!AA149,Anchieta!AA107,Corporativo!T77,'Compras '!X149,Vendas!T88,'Diretoria Financeira'!T73) -> #REF! | ... AH58: =SUM(Diadema!AE181,Ferraz!AD149,'São Leopoldo'!AD111,Jarinu!AD149,Anchieta!AD107,Corporativo!W77,'Compras '!AA149,Vendas!W88,'Diretoria Financeira'!W73) -> #REF!
D59: 4 | E59: =_xlfn.XLOOKUP(F59,Pareto!S:S,Pareto!T:T) -> Jarinu | F59: =_xlfn.XLOOKUP(K59,Pareto!V:V,Pareto!S:S) -> 36 - Venda Robos | H59: =_xlfn.XLOOKUP(F59,Pareto!S:S,Pareto!X:X) -> ✓ Concluído | I59: =_xlfn.XLOOKUP('5 Unidades +'!F59,Pareto!S:S,Pareto!Z:Z) -> OK | J59: =_xlfn.XLOOKUP(F59,Pareto!S:S,Pareto!U:U) -> 0 | K59: =IFERROR(LARGE(Pareto!V:V,D59)," ") -> 390000 | L59: =_xlfn.XLOOKUP(F59,Pareto!S:S,Pareto!W:W) -> 390000 | M59: =IF(L59="",-K59,L59-K59) -> -0.003 | V59: Acumulado Previsto | W59: =W56 -> 1727858.4 | X59: =W59+X56 -> 3129114.3 | Y59: =X59+Y56 -> 4976284.8 | Z59: =Y59+Z56 -> 6906456.4 | AA59: =Z59+AA56 -> 9014941.3 | AB59: =AA59+AB56 -> 11709787 | AC59: =AB59+AC56 -> 14659428 | AD59: =AC59+AD56 -> 18408687 | AE59: =AD59+AE56 -> 22455993 | ... AH59: =AG59+AH56 -> 40637373
D60: 5 | E60: =_xlfn.XLOOKUP(F60,Pareto!S:S,Pareto!T:T) -> Ferraz | F60: =_xlfn.XLOOKUP(K60,Pareto!V:V,Pareto!S:S) -> 06 - Reaproveitamento de lixas | H60: =_xlfn.XLOOKUP(F60,Pareto!S:S,Pareto!X:X) -> ✓ Concluído | I60: =_xlfn.XLOOKUP('5 Unidades +'!F60,Pareto!S:S,Pareto!Z:Z) -> OK | J60: =_xlfn.XLOOKUP(F60,Pareto!S:S,Pareto!U:U) -> 151815.13 | K60: =IFERROR(LARGE(Pareto!V:V,D60)," ") -> 354235.3 | L60: =_xlfn.XLOOKUP(F60,Pareto!S:S,Pareto!W:W) -> 276395.48 | M60: =IF(L60="",-K60,L60-K60) -> -77839.823 | V60: Acumulado Real | W60: =W57 -> 823549.22 | X60: =W60+X57 -> 1507384.2 | Y60: =X60+Y57 -> 2338102.5 | Z60: =Y60+Z57 -> 3150736.4 | AA60: =Z60+AA57 -> 4148030.6 | AB60: =AA60+AB57 -> 5280873.8 | AC60: =AB60+AC57 -> 5605985.8 | AD60: =AC60+AD57 -> 5623569.8 | AE60: =AD60+AE57 -> 5623569.8 | ... AH60: =AG60+AH57 -> 5623569.8
D61: 6 | E61: =_xlfn.XLOOKUP(F61,Pareto!S:S,Pareto!T:T) -> Ferraz | F61: =_xlfn.XLOOKUP(K61,Pareto!V:V,Pareto!S:S) -> 03 - Consumo de desmoldante | H61: =_xlfn.XLOOKUP(F61,Pareto!S:S,Pareto!X:X) -> ✓ Concluído | I61: =_xlfn.XLOOKUP('5 Unidades +'!F61,Pareto!S:S,Pareto!Z:Z) -> OK | J61: =_xlfn.XLOOKUP(F61,Pareto!S:S,Pareto!U:U) -> 126310.64 | K61: =IFERROR(LARGE(Pareto!V:V,D61)," ") -> 294724.83 | L61: =_xlfn.XLOOKUP(F61,Pareto!S:S,Pareto!W:W) -> 525129.73 | M61: =IF(L61="",-K61,L61-K61) -> 230404.9 | P61: , | V61: Projeção da Meta | W61: =W60 -> 823549.22 | X61: =IF(AND(ISNUMBER(X57),X57<>0), X60, W61 + ((Parâmetros!$E$15 - MAX($W$60:$AI$60)) / COUNTIF($W$57:$AI$57,0))) -> 1507384.2 | Y61: =IF(AND(ISNUMBER(Y57),Y57<>0), Y60, X61 + ((Parâmetros!$E$15 - MAX($W$60:$AI$60)) / COUNTIF($W$57:$AI$57,0))) -> 2338102.5 | Z61: =IF(AND(ISNUMBER(Z57),Z57<>0), Z60, Y61 + ((Parâmetros!$E$15 - MAX($W$60:$AI$60)) / COUNTIF($W$57:$AI$57,0))) -> 3150736.4 | AA61: =IF(AND(ISNUMBER(AA57),AA57<>0), AA60, Z61 + ((Parâmetros!$E$15 - MAX($W$60:$AI$60)) / COUNTIF($W$57:$AI$57,0))) -> 4148030.6 | AB61: =IF(AND(ISNUMBER(AB57),AB57<>0), AB60, AA61 + ((Parâmetros!$E$15 - MAX($W$60:$AI$60)) / COUNTIF($W$57:$AI$57,0))) -> 5280873.8 | AC61: =IF(AND(ISNUMBER(AC57),AC57<>0), AC60, AB61 + ((Parâmetros!$E$15 - MAX($W$60:$AI$60)) / COUNTIF($W$57:$AI$57,0))) -> 5605985.8 | AD61: =IF(AND(ISNUMBER(AD57),AD57<>0), AD60, AC61 + ((Parâmetros!$E$15 - MAX($W$60:$AI$60)) / COUNTIF($W$57:$AI$57,0))) -> 5623569.8 | AE61: =IF(AND(ISNUMBER(AE57),AE57<>0), AE60, AD61 + ((Parâmetros!$E$15 - MAX($W$60:$AI$60)) / COUNTIF($W$57:$AI$57,0))) -> 16797677 | ... AH61: =IF(AND(ISNUMBER(AH57),AH57<>0), AH60, AG61 + ((Parâmetros!$E$15 - MAX($W$60:$AI$60)) / COUNTIF($W$57:$AI$57,0))) -> 50320000
D62: 7 | E62: =_xlfn.XLOOKUP(F62,Pareto!S:S,Pareto!T:T) -> Ferraz | F62: =_xlfn.XLOOKUP(K62,Pareto!V:V,Pareto!S:S) -> 03 - Consumo de desmoldante | H62: =_xlfn.XLOOKUP(F62,Pareto!S:S,Pareto!X:X) -> ✓ Concluído | I62: =_xlfn.XLOOKUP('5 Unidades +'!F62,Pareto!S:S,Pareto!Z:Z) -> OK | J62: =_xlfn.XLOOKUP(F62,Pareto!S:S,Pareto!U:U) -> 126310.64 | K62: =IFERROR(LARGE(Pareto!V:V,D62)," ") -> 294724.83 | L62: =_xlfn.XLOOKUP(F62,Pareto!S:S,Pareto!W:W) -> 525129.73 | M62: =IF(L62="",-K62,L62-K62) -> 230404.9 | V62: Acumulado prev.Custos | W62: =W63 -> 886433.43 | X62: =W62+X63 -> 1357922.2 | Y62: =X62+Y63 -> 2131437.1 | Z62: =Y62+Z63 -> 2954336.8 | AA62: =Z62+AA63 -> 3889491.6 | AB62: =AA62+AB63 -> 5176381.8 | AC62: =AB62+AC63 -> 6575785.2 | AD62: =AC62+AD63 -> 8109702.2 | AE62: =AD62+AE63 -> 9657948.6 | ... AH62: =AG62+AH63 -> 15701522
D63: 8 | E63: =_xlfn.XLOOKUP(F63,Pareto!S:S,Pareto!T:T) -> Ferraz | F63: =_xlfn.XLOOKUP(K63,Pareto!V:V,Pareto!S:S) -> 07 - Consumo de gás | H63: =_xlfn.XLOOKUP(F63,Pareto!S:S,Pareto!X:X) -> ✓ Concluído | I63: =_xlfn.XLOOKUP('5 Unidades +'!F63,Pareto!S:S,Pareto!Z:Z) -> OK | J63: =_xlfn.XLOOKUP(F63,Pareto!S:S,Pareto!U:U) -> 101344.25 | K63: =IFERROR(LARGE(Pareto!V:V,D63)," ") -> 236469.92 | L63: =_xlfn.XLOOKUP(F63,Pareto!S:S,Pareto!W:W) -> 413825.57 | M63: =IF(L63="",-K63,L63-K63) -> 177355.65 | V63: Custos | W63: =Diadema!T185+Jarinu!S153+Ferraz!S153+'São Leopoldo'!S115+Anchieta!S111+'Compras '!P153+Vendas!L92 -> 886433.43 | X63: =Diadema!U185+Jarinu!T153+Ferraz!T153+'São Leopoldo'!T115+Anchieta!T111+'Compras '!Q153+Vendas!M92 -> 471488.78 | Y63: =Diadema!V185+Jarinu!U153+Ferraz!U153+'São Leopoldo'!U115+Anchieta!U111+'Compras '!R153+Vendas!N92 -> 773514.92 | Z63: =Diadema!W185+Jarinu!V153+Ferraz!V153+'São Leopoldo'!V115+Anchieta!V111+'Compras '!S153+Vendas!O92 -> 822899.7 | AA63: =Diadema!X185+Jarinu!W153+Ferraz!W153+'São Leopoldo'!W115+Anchieta!W111+'Compras '!T153+Vendas!P92 -> 935154.76 | AB63: =Diadema!Y185+Jarinu!X153+Ferraz!X153+'São Leopoldo'!X115+Anchieta!X111+'Compras '!U153+Vendas!Q92 -> 1286890.3 | AC63: =Diadema!Z185+Jarinu!Y153+Ferraz!Y153+'São Leopoldo'!Y115+Anchieta!Y111+'Compras '!V153+Vendas!R92 -> 1399403.4 | AD63: =Diadema!AA185+Jarinu!Z153+Ferraz!Z153+'São Leopoldo'!Z115+Anchieta!Z111+'Compras '!W153+Vendas!S92 -> 1533917 | ... AH63: =Diadema!AE185+Jarinu!AD153+Ferraz!AD153+'São Leopoldo'!AD115+Anchieta!AD111+'Compras '!AA153+Vendas!W92 -> 2023193.3 | AI63: =SUM(W63:AH63) -> 15701522
D64: 9 | E64: =_xlfn.XLOOKUP(F64,Pareto!S:S,Pareto!T:T) -> Diadema | F64: =_xlfn.XLOOKUP(K64,Pareto!V:V,Pareto!S:S) -> 29 - DA000489Z_DA000490Z - STC Scania M_ | H64: =_xlfn.XLOOKUP(F64,Pareto!S:S,Pareto!X:X) -> ✓ Concluído | I64: =_xlfn.XLOOKUP('5 Unidades +'!F64,Pareto!S:S,Pareto!Z:Z) -> OK | J64: =_xlfn.XLOOKUP(F64,Pareto!S:S,Pareto!U:U) -> 446423.79 | K64: =IFERROR(LARGE(Pareto!V:V,D64)," ") -> 223211.9 | L64: =_xlfn.XLOOKUP(F64,Pareto!S:S,Pareto!W:W) -> 282888.46 | M64: =IF(L64="",-K64,L64-K64) -> 59676.57
...

Sheet Diadema
A1: DASHBOARD EXECUTIVO - UNIDADE DIADEMA
A2: Gestão Estratégica de Projetos e Redução de Custos | Grupo Delga | 2026
A4: META DA UNIDADE 2026 | B4: RETORNO PREVISTO (Anual) | C4: Retorno Validado (Anual) | D4: PREVISTO 2026 | E4: 💰 RETORNO VALIDADO 2026 | G4: 💰 RETORNO REAL 2026 | I4: Extra DRE (Até o momento) | J4: % ATINGIMENTO DA META 2026 | L4: INICIATIVAS | O4: TOP 20 Raking de Projetos Valorizados | AP4: dip | AQ4: perf | AU4: 2025 | AV4: 2026
A5: =Parâmetros!E5 -> 6947000 | B5: =SUM(I55:I176) -> 4661058.2 | C5: =AV53 -> 4424279.6 | D5: =AU53 -> 2988619.3 | E5: =SUM(N55:N176) -> 2877285.2 | G5: =SUM(E9,E11:E13) -> 1008796 | I5: =E8+E10 -> 137181.16 | J5: =G5/A5 -> 0.14521318 | L5: =SUM(G8:G10) -> 57 | O5: POS | P5: Tipo | Q5: Valor Previsto Unidade | R5: Valor Previsto Custos | S5: Retorno Previsto | T5: Retorno Real até hoje | U5: Projetos | Z5: Peso | AA5: Pareto | AB5: % Previsto | AC5: % Real | AD5: Planejado | AE5: % Responsabilidade Delga | AS5: 0.3293 | AT5: 0.9228 | AW5: p | AX5: 0.9261 | AY5: 0.95
A6: 📊 SAVING PREVISTO POR PILAR | F6: 📋 STATUS DAS INICIATIVAS | I6: 🏭 INDICADORES OPERACIONAIS | O6: {=_xlfn.SEQUENCE(20)} -> 1 | P6: =_xlfn.XLOOKUP(U6,$C$55:$C$176,$A$55:$A$176) -> BSW | Q6: =MAX(I55:I176) -> 450000.01 | R6: =_xlfn.XLOOKUP(Q6,$I$55:$I$176,$N$55:$N$176) -> 446423.79 | S6: =_xlfn.XLOOKUP(U6,$C$55:$C$176,$J$55:$J$176) -> 46082 | T6: {=SUMPRODUCT(($C$55:$C$175=U6)*(U$54:$AI$54<=TODAY())*(ISNUMBER(U$56:$AI$176)),U$56:$AI$176)} -> 282888.46 | U6: =IFERROR(HYPERLINK(INDEX($D$55:$D$176,MATCH(Q6,$I$55:$I$176,0)),INDEX($C$55:$C$176,MATCH(Q6,$I$55:$I$176,0)) ), ) -> 29 - DA000489Z_DA000490Z - STC Scania M_ | Z6: =Q6/$C$5 -> 0.10171148 | AA6: =Z6 -> 0.10171148 | AB6: {=IFERROR(INDEX($T$55:$T$176,MATCH(1,($AP$55:$AP$176=U6)*($S$55:$S$176="Previsto"), 0) ), "")} -> 1 | AC6: {=IFERROR( INDEX($T$55:$T$176,MATCH(1,($AP$55:$AP$176=U6)*($S$55:$S$176="Real"),0)),"")} -> 1 | AD6: =IF(OR(AB6="",AC6=""),"",IF(AC6=100%,"CONCLUÍDO",IF(AC6=0,IF(AB6=0,"PROJETO NÃO INICIADO","FALTA DE ACOMPANHAMENTO"),IF(AC6>AB6,"ADIANTADO",IF(AC6=AB6,"CONFORME PLANEJADO","ATRASO"))))) -> CONCLUÍDO | AE6: {=_xlfn.XLOOKUP($U$6:$U$25,$C$55:$C$176,$R$55:$R$176)} -> 1 | AS6: 0.4166 | AT6: 0.9152 | AW6: d | AX6: 0.5017 | AY6: 0.58
A7: Pilar | B7: Qtd. | C7: Saving (R$) | D7: Saving Validado 2026 | E7: Até o Momento | F7: Status | G7: Qtd. | H7: R$ Previsto | I7: Aderência SPD: Unidade | J7: Aderência SPD: Auditado | K7: Análise de Margem (Form 206) | O7: 2 | P7: =_xlfn.XLOOKUP(U7,$C$55:$C$176,$A$55:$A$176) -> BSW | Q7: =IFERROR(LARGE($I$55:$I$176,O7)," ") -> 331600 | R7: =_xlfn.XLOOKUP(Q7,$I$55:$I$176,$N$55:$N$176) -> 160178.29 | S7: =_xlfn.XLOOKUP(U7,$C$55:$C$176,$J$55:$J$176) -> 46082 | T7: {=SUMPRODUCT(($C$55:$C$175=U7)*(U$54:$AI$54<=TODAY())*(ISNUMBER(U$56:$AI$176)),U$56:$AI$176)} -> 84365.272 | U7: =IFERROR(HYPERLINK(INDEX($D$55:$D$176,MATCH(Q7,$I$55:$I$176,0)),INDEX($C$55:$C$176,MATCH(Q7,$I$55:$I$176,0)) ), "" ) -> 01 - Redução de peso bruto DA000489A | Z7: =Q7/$C$5 -> 0.074950056 | AA7: =Z7+AA6 -> 0.17666153 | AB7: {=IFERROR(INDEX($T$55:$T$176,MATCH(1,($AP$55:$AP$176=U7)*($S$55:$S$176="Previsto"), 0) ), "")} -> 1 | AC7: {=IFERROR( INDEX($T$55:$T$176,MATCH(1,($AP$55:$AP$176=U7)*($S$55:$S$176="Real"),0)),"")} -> 1 | AD7: =IF(OR(AB7="",AC7=""),"",IF(AC7=100%,"CONCLUÍDO",IF(AC7=0,IF(AB7=0,"PROJETO NÃO INICIADO","FALTA DE ACOMPANHAMENTO"),IF(AC7>AB7,"ADIANTADO",IF(AC7=AB7,"CONFORME PLANEJADO","ATRASO"))))) -> CONCLUÍDO | AE7: 1 | AS7: 0.4666 | AT7: 0.9202 | AW7: q | AX7: 0.955 | AY7: 0.965
A8: Kaizen - Capital de Giro | B8: =COUNTIF($A$55:$A$176,A8) -> 0 | C8: =SUMIF($A$55:$A$176,A8,$I$55:$I$176) -> 0 | D8: =SUMIF($A$55:$A$176,A8,$N$55:$N$176) -> 0 | E8: =SUMIFS($AK$55:$AK$176,$S$55:$S$176,"Previsto",$AS$55:$AS$176,A8) -> 0 | F8: ✓ Concluído | G8: =COUNTIF($O$55:$O$176,F8) -> 45 | H8: =SUMIF($O$55:$O$176,F8,$I$55:$I$176) -> 3446352.2 | O8: 3 | P8: =_xlfn.XLOOKUP(U8,$C$55:$C$176,$A$55:$A$176) -> Kaizen - Ganho Recorrente | Q8: =IFERROR(LARGE($I$55:$I$176,O8)," ") -> 288000 | R8: =_xlfn.XLOOKUP(Q8,$I$55:$I$176,$N$55:$N$176) -> 189414 | S8: =_xlfn.XLOOKUP(U8,$C$55:$C$176,$J$55:$J$176) -> 46143 | T8: {=SUMPRODUCT(($C$55:$C$175=U8)*(U$54:$AI$54<=TODAY())*(ISNUMBER(U$56:$AI$176)),U$56:$AI$176)} -> 17242 | U8: =IFERROR(HYPERLINK(INDEX($D$55:$D$176,MATCH(Q8,$I$55:$I$176,0)),INDEX($C$55:$C$176,MATCH(Q8,$I$55:$I$176,0)) ), "" ) -> 06 - Produtividade | Z8: =Q8/$C$5 -> 0.065095344 | AA8: =Z8+AA7 -> 0.24175688 | AB8: {=IFERROR(INDEX($T$55:$T$176,MATCH(1,($AP$55:$AP$176=U8)*($S$55:$S$176="Previsto"), 0) ), "")} -> 0.96 | AC8: {=IFERROR( INDEX($T$55:$T$176,MATCH(1,($AP$55:$AP$176=U8)*($S$55:$S$176="Real"),0)),"")} -> 0.98 | AD8: =IF(OR(AB8="",AC8=""),"",IF(AC8=100%,"CONCLUÍDO",IF(AC8=0,IF(AB8=0,"PROJETO NÃO INICIADO","FALTA DE ACOMPANHAMENTO"),IF(AC8>AB8,"ADIANTADO",IF(AC8=AB8,"CONFORME PLANEJADO","ATRASO"))))) -> ADIANTADO | AE8: 1 | AT8: 0.5436 | AU8: 0.9206 | AY8: =AX7*AX6*AX5 -> 0.44371627 | AZ8: =AY7*AY6*AY5 -> 0.531715
A9: Kaizen - Ganho Recorrente | B9: =COUNTIF($A$55:$A$176,A9) -> 16 | C9: =SUMIF($A$55:$A$176,A9,$I$55:$I$176) -> 1102734.3 | D9: =SUMIF($A$55:$A$176,A9,$N$55:$N$176) -> 651481.3 | E9: =SUMIFS($AK$55:$AK$176,$S$55:$S$176,"Real",$AS$55:$AS$176,A9) -> 237950.7 | F9: ⏳ Em Execução | G9: =COUNTIF($O$55:$O$176,F9) -> 12 | H9: =SUMIF($O$55:$O$176,F9,$I$55:$I$176) -> 1214706 | I9: =E207 -> 1 | J9: =F207 -> 0.91666667 | K9: =L214 -> 0.25252525 | O9: 4 | P9: =_xlfn.XLOOKUP(U9,$C$55:$C$176,$A$55:$A$176) -> BSW | Q9: =IFERROR(LARGE($I$55:$I$176,O9)," ") -> 288000 | R9: =_xlfn.XLOOKUP(Q9,$I$55:$I$176,$N$55:$N$176) -> 175018.02 | S9: =_xlfn.XLOOKUP(U9,$C$55:$C$176,$J$55:$J$176) -> 46143 | T9: {=SUMPRODUCT(($C$55:$C$175=U9)*(U$54:$AI$54<=TODAY())*(ISNUMBER(U$56:$AI$176)),U$56:$AI$176)} -> 51802.779 | U9: =IFERROR(HYPERLINK(INDEX($D$55:$D$176,MATCH(Q9,$I$55:$I$176,0)),INDEX($C$55:$C$176,MATCH(Q9,$I$55:$I$176,0)) ), "" ) -> 26 - Redução_de_MP - DJ000059Z_DJ000060Z | Z9: =Q9/$C$5 -> 0.065095344 | AA9: =Z9+AA8 -> 0.30685222 | AB9: {=IFERROR(INDEX($T$55:$T$176,MATCH(1,($AP$55:$AP$176=U9)*($S$55:$S$176="Previsto"), 0) ), "")} -> 1 | AC9: {=IFERROR( INDEX($T$55:$T$176,MATCH(1,($AP$55:$AP$176=U9)*($S$55:$S$176="Real"),0)),"")} -> 1 | AD9: =IF(OR(AB9="",AC9=""),"",IF(AC9=100%,"CONCLUÍDO",IF(AC9=0,IF(AB9=0,"PROJETO NÃO INICIADO","FALTA DE ACOMPANHAMENTO"),IF(AC9>AB9,"ADIANTADO",IF(AC9=AB9,"CONFORME PLANEJADO","ATRASO"))))) -> CONCLUÍDO | AE9: 1 | AT9: 0.5123 | AU9: 0.923
A10: Kaizen - Custo Evitado | B10: =COUNTIF($A$55:$A$176,A10) -> 4 | C10: =SUMIF($A$55:$A$176,A10,$I$55:$I$176) -> 137181.16 | D10: =SUMIF($A$55:$A$176,A10,$N$55:$N$176) -> 0 | E10: =SUMIFS($AK$55:$AK$176,$S$55:$S$176,"Previsto",$AS$55:$AS$176,A10) -> 137181.16 | F10: 📝 Não iniciado | G10: =COUNTIF($O$55:$O$176,F10) -> 0 | H10: =SUMIF($O$55:$O$176,F10,$I$55:$I$176) -> 0 | O10: 5 | P10: =_xlfn.XLOOKUP(U10,$C$55:$C$176,$A$55:$A$176) -> BSW | Q10: =IFERROR(LARGE($I$55:$I$176,O10)," ") -> 270000 | R10: =_xlfn.XLOOKUP(Q10,$I$55:$I$176,$N$55:$N$176) -> 128107.04 | S10: =_xlfn.XLOOKUP(U10,$C$55:$C$176,$J$55:$J$176) -> 46235 | T10: {=SUMPRODUCT(($C$55:$C$175=U10)*(U$54:$AI$54<=TODAY())*(ISNUMBER(U$56:$AI$176)),U$56:$AI$176)} -> 0 | U10: =IFERROR(HYPERLINK(INDEX($D$55:$D$176,MATCH(Q10,$I$55:$I$176,0)),INDEX($C$55:$C$176,MATCH(Q10,$I$55:$I$176,0)) ), "" ) -> 23 - Redução do peso bruto VW000581Z / VW000582Z | Z10: =Q10/$C$5 -> 0.061026885 | AA10: =Z10+AA9 -> 0.36787911 | AB10: {=IFERROR(INDEX($T$55:$T$176,MATCH(1,($AP$55:$AP$176=U10)*($S$55:$S$176="Previsto"), 0) ), "")} -> 0.2 | AC10: {=IFERROR( INDEX($T$55:$T$176,MATCH(1,($AP$55:$AP$176=U10)*($S$55:$S$176="Real"),0)),"")} -> 0.25 | AD10: =IF(OR(AB10="",AC10=""),"",IF(AC10=100%,"CONCLUÍDO",IF(AC10=0,IF(AB10=0,"PROJETO NÃO INICIADO","FALTA DE ACOMPANHAMENTO"),IF(AC10>AB10,"ADIANTADO",IF(AC10=AB10,"CONFORME PLANEJADO","ATRASO"))))) -> ADIANTADO | AE10: 0.8 | AT10: 0.5216 | AU10: 0.9165
A11: Redução de Custo | B11: =COUNTIF($A$55:$A$176,A11) -> 0 | C11: =SUMIF($A$55:$A$176,A11,$I$55:$I$176) -> 0 | D11: =SUMIF($A$55:$A$176,B11,$I$55:$I$176) -> 0 | E11: =SUMIFS($AK$55:$AK$176,$S$55:$S$176,"Real",$AS$55:$AS$176,A11) -> 0 | O11: 6 | P11: =_xlfn.XLOOKUP(U11,$C$55:$C$176,$A$55:$A$176) -> BSW | Q11: =IFERROR(LARGE($I$55:$I$176,O11)," ") -> 236000 | R11: =_xlfn.XLOOKUP(Q11,$I$55:$I$176,$N$55:$N$176) -> 77354.64 | S11: =_xlfn.XLOOKUP(U11,$C$55:$C$176,$J$55:$J$176) -> 46174 | T11: {=SUMPRODUCT(($C$55:$C$175=U11)*(U$54:$AI$54<=TODAY())*(ISNUMBER(U$56:$AI$176)),U$56:$AI$176)} -> 12498.573 | U11: =IFERROR(HYPERLINK(INDEX($D$55:$D$176,MATCH(Q11,$I$55:$I$176,0)),INDEX($C$55:$C$176,MATCH(Q11,$I$55:$I$176,0)) ), "" ) -> 52 - Redução de MP - GM000458Z / GM000459Z | Z11: =Q11/$C$5 -> 0.053342018 | AA11: =Z11+AA10 -> 0.42122112 | AB11: {=IFERROR(INDEX($T$55:$T$176,MATCH(1,($AP$55:$AP$176=U11)*($S$55:$S$176="Previsto"), 0) ), "")} -> 1 | AC11: {=IFERROR( INDEX($T$55:$T$176,MATCH(1,($AP$55:$AP$176=U11)*($S$55:$S$176="Real"),0)),"")} -> 1 | AD11: =IF(OR(AB11="",AC11=""),"",IF(AC11=100%,"CONCLUÍDO",IF(AC11=0,IF(AB11=0,"PROJETO NÃO INICIADO","FALTA DE ACOMPANHAMENTO"),IF(AC11>AB11,"ADIANTADO",IF(AC11=AB11,"CONFORME PLANEJADO","ATRASO"))))) -> CONCLUÍDO | AE11: 1 | AT11: 0.5217 | AU11: 0.9237
A12: Você Resolve | B12: =COUNTIF($A$55:$A$176,A12) -> 0 | C12: =SUMIF($A$55:$A$176,A12,$I$55:$I$176) -> 0 | D12: =SUMIF($A$55:$A$176,A12,$N$55:$N$176) -> 0 | E12: =SUMIFS($AK$55:$AK$176,$S$55:$S$176,"Real",$AS$55:$AS$176,A12) -> 0 | O12: 7 | P12: =_xlfn.XLOOKUP(U12,$C$55:$C$176,$A$55:$A$176) -> BSW | Q12: =IFERROR(LARGE($I$55:$I$176,O12)," ") -> 230000 | R12: =_xlfn.XLOOKUP(Q12,$I$55:$I$176,$N$55:$N$176) -> 115018 | S12: =_xlfn.XLOOKUP(U12,$C$55:$C$176,$J$55:$J$176) -> 46204 | T12: {=SUMPRODUCT(($C$55:$C$175=U12)*(U$54:$AI$54<=TODAY())*(ISNUMBER(U$56:$AI$176)),U$56:$AI$176)} -> 28959.052 | U12: =IFERROR(HYPERLINK(INDEX($D$55:$D$176,MATCH(Q12,$I$55:$I$176,0)),INDEX($C$55:$C$176,MATCH(Q12,$I$55:$I$176,0)) ), "" ) -> 44 - Mudança de fonte Usiminas para Arcelor | Z12: =Q12/$C$5 -> 0.051985865 | AA12: =Z12+AA11 -> 0.47320699 | AB12: {=IFERROR(INDEX($T$55:$T$176,MATCH(1,($AP$55:$AP$176=U12)*($S$55:$S$176="Previsto"), 0) ), "")} -> 0.29 | AC12: {=IFERROR( INDEX($T$55:$T$176,MATCH(1,($AP$55:$AP$176=U12)*($S$55:$S$176="Real"),0)),"")} -> 0.36 | AD12: =IF(OR(AB12="",AC12=""),"",IF(AC12=100%,"CONCLUÍDO",IF(AC12=0,IF(AB12=0,"PROJETO NÃO INICIADO","FALTA DE ACOMPANHAMENTO"),IF(AC12>AB12,"ADIANTADO",IF(AC12=AB12,"CONFORME PLANEJADO","ATRASO"))))) -> ADIANTADO | AE12: 0.2 | AT12: 0.5746 | AU12: 0.936
A13: BSW | B13: =COUNTIF($A$55:$A$176,A13) -> 37 | C13: =SUMIF($A$55:$A$176,A13,$I$55:$I$176) -> 3421142.7 | D13: =SUMIF($A$55:$A$176,A13,$N$55:$N$176) -> 2225803.9 | E13: =SUMIFS($AK$55:$AK$176,$S$55:$S$176,"Real",$AS$55:$AS$176,A13) -> 770845.29 | O13: 8 | P13: =_xlfn.XLOOKUP(U13,$C$55:$C$176,$A$55:$A$176) -> Kaizen - Ganho Recorrente | Q13: =IFERROR(LARGE($I$55:$I$176,O13)," ") -> 228000 | R13: =_xlfn.XLOOKUP(Q13,$I$55:$I$176,$N$55:$N$176) -> 152396 | S13: =_xlfn.XLOOKUP(U13,$C$55:$C$176,$J$55:$J$176) -> 46082 | T13: {=SUMPRODUCT(($C$55:$C$175=U13)*(U$54:$AI$54<=TODAY())*(ISNUMBER(U$56:$AI$176)),U$56:$AI$176)} -> 72521 | U13: =IFERROR(HYPERLINK(INDEX($D$55:$D$176,MATCH(Q13,$I$55:$I$176,0)),INDEX($C$55:$C$176,MATCH(Q13,$I$55:$I$176,0)) ), "" ) -> 16 - Eficiência de MO na linha de Solda e Montagem | Z13: =Q13/$C$5 -> 0.051533814 | AA13: =Z13+AA12 -> 0.5247408 | AB13: {=IFERROR(INDEX($T$55:$T$176,MATCH(1,($AP$55:$AP$176=U13)*($S$55:$S$176="Previsto"), 0) ), "")} -> 1 | AC13: {=IFERROR( INDEX($T$55:$T$176,MATCH(1,($AP$55:$AP$176=U13)*($S$55:$S$176="Real"),0)),"")} -> 1 | AD13: =IF(OR(AB13="",AC13=""),"",IF(AC13=100%,"CONCLUÍDO",IF(AC13=0,IF(AB13=0,"PROJETO NÃO INICIADO","FALTA DE ACOMPANHAMENTO"),IF(AC13>AB13,"ADIANTADO",IF(AC13=AB13,"CONFORME PLANEJADO","ATRASO"))))) -> CONCLUÍDO | AE13: 1 | AT13: 0.5423 | AU13: 0.936
A14: TOTAL | B14: =SUM(B8:B13) -> 57 | C14: =SUM(C8:C13) -> 4661058.2 | D14: =SUM(D8:D13) -> 2877285.2 | E14: =SUM(E8:E13) -> 1145977.2 | O14: 9 | P14: =_xlfn.XLOOKUP(U14,$C$55:$C$176,$A$55:$A$176) -> BSW | Q14: =IFERROR(LARGE($I$55:$I$176,O14)," ") -> 223200 | R14: =_xlfn.XLOOKUP(Q14,$I$55:$I$176,$N$55:$N$176) -> 202515.94 | S14: =_xlfn.XLOOKUP(U14,$C$55:$C$176,$J$55:$J$176) -> 46174 | T14: {=SUMPRODUCT(($C$55:$C$175=U14)*(U$54:$AI$54<=TODAY())*(ISNUMBER(U$56:$AI$176)),U$56:$AI$176)} -> 27146.624 | U14: =IFERROR(HYPERLINK(INDEX($D$55:$D$176,MATCH(Q14,$I$55:$I$176,0)),INDEX($C$55:$C$176,MATCH(Q14,$I$55:$I$176,0)) ), "" ) -> 57 - AlmaCAM_Redução de Peso | Z14: =Q14/$C$5 -> 0.050448891 | AA14: =Z14+AA13 -> 0.57518969 | AB14: {=IFERROR(INDEX($T$55:$T$176,MATCH(1,($AP$55:$AP$176=U14)*($S$55:$S$176="Previsto"), 0) ), "")} -> 1 | AC14: {=IFERROR( INDEX($T$55:$T$176,MATCH(1,($AP$55:$AP$176=U14)*($S$55:$S$176="Real"),0)),"")} -> 1 | AD14: =IF(OR(AB14="",AC14=""),"",IF(AC14=100%,"CONCLUÍDO",IF(AC14=0,IF(AB14=0,"PROJETO NÃO INICIADO","FALTA DE ACOMPANHAMENTO"),IF(AC14>AB14,"ADIANTADO",IF(AC14=AB14,"CONFORME PLANEJADO","ATRASO"))))) -> CONCLUÍDO | AE14: 1 | AS14: 0.5472 | AT14: 0.9115
F15: VA | G15: =SUMIF($B$55:$B$176,F15,$N$55:$N$176) -> 2225803.9 | O15: 10 | P15: =_xlfn.XLOOKUP(U15,$C$55:$C$176,$A$55:$A$176) -> Kaizen - Ganho Recorrente | Q15: =IFERROR(LARGE($I$55:$I$176,O15)," ") -> 210000 | R15: =_xlfn.XLOOKUP(Q15,$I$55:$I$176,$N$55:$N$176) -> 122500 | S15: =_xlfn.XLOOKUP(U15,$C$55:$C$176,$J$55:$J$176) -> 46174 | T15: {=SUMPRODUCT(($C$55:$C$175=U15)*(U$54:$AI$54<=TODAY())*(ISNUMBER(U$56:$AI$176)),U$56:$AI$176)} -> 35000 | U15: =IFERROR(HYPERLINK(INDEX($D$55:$D$176,MATCH(Q15,$I$55:$I$176,0)),INDEX($C$55:$C$176,MATCH(Q15,$I$55:$I$176,0)) ), "" ) -> 42 - Aluguel de Compressor | Z15: =Q15/$C$5 -> 0.047465355 | AA15: =Z15+AA14 -> 0.62265505 | AB15: {=IFERROR(INDEX($T$55:$T$176,MATCH(1,($AP$55:$AP$176=U15)*($S$55:$S$176="Previsto"), 0) ), "")} -> 1 | AC15: {=IFERROR( INDEX($T$55:$T$176,MATCH(1,($AP$55:$AP$176=U15)*($S$55:$S$176="Real"),0)),"")} -> 1 | AD15: =IF(OR(AB15="",AC15=""),"",IF(AC15=100%,"CONCLUÍDO",IF(AC15=0,IF(AB15=0,"PROJETO NÃO INICIADO","FALTA DE ACOMPANHAMENTO"),IF(AC15>AB15,"ADIANTADO",IF(AC15=AB15,"CONFORME PLANEJADO","ATRASO"))))) -> CONCLUÍDO | AE15: 1 | AS15: 0.5483 | AT15: 0.9229
F16: GGF | G16: =SUMIF($B$55:$B$176,F16,$N$55:$N$176) -> 605429.3 | O16: 11 | P16: =_xlfn.XLOOKUP(U16,$C$55:$C$176,$A$55:$A$176) -> BSW | Q16: =IFERROR(LARGE($I$55:$I$176,O16)," ") -> 189200 | R16: =_xlfn.XLOOKUP(Q16,$I$55:$I$176,$N$55:$N$176) -> 70963.59 | S16: =_xlfn.XLOOKUP(U16,$C$55:$C$176,$J$55:$J$176) -> 46235 | T16: {=SUMPRODUCT(($C$55:$C$175=U16)*(U$54:$AI$54<=TODAY())*(ISNUMBER(U$56:$AI$176)),U$56:$AI$176)} -> 0 | U16: =IFERROR(HYPERLINK(INDEX($D$55:$D$176,MATCH(Q16,$I$55:$I$176,0)),INDEX($C$55:$C$176,MATCH(Q16,$I$55:$I$176,0)) ), "" ) -> 47 - REDUÇÃO DE MP DJ000079Z – 80Z | Z16: =Q16/$C$5 -> 0.042764024 | AA16: =Z16+AA15 -> 0.66541907 | AB16: {=IFERROR(INDEX($T$55:$T$176,MATCH(1,($AP$55:$AP$176=U16)*($S$55:$S$176="Previsto"), 0) ), "")} -> 0.24 | AC16: {=IFERROR( INDEX($T$55:$T$176,MATCH(1,($AP$55:$AP$176=U16)*($S$55:$S$176="Real"),0)),"")} -> 0.38 | AD16: =IF(OR(AB16="",AC16=""),"",IF(AC16=100%,"CONCLUÍDO",IF(AC16=0,IF(AB16=0,"PROJETO NÃO INICIADO","FALTA DE ACOMPANHAMENTO"),IF(AC16>AB16,"ADIANTADO",IF(AC16=AB16,"CONFORME PLANEJADO","ATRASO"))))) -> ADIANTADO | AE16: 0.5 | AS16: 0.4958 | AT16: 0.9642
F17: MA | G17: =SUMIF($B$55:$B$176,F17,$N$55:$N$176) -> 0 | O17: 12 | P17: =_xlfn.XLOOKUP(U17,$C$55:$C$176,$A$55:$A$176) -> BSW | Q17: =IFERROR(LARGE($I$55:$I$176,O17)," ") -> 115000 | R17: =_xlfn.XLOOKUP(Q17,$I$55:$I$176,$N$55:$N$176) -> 39111.77 | S17: =_xlfn.XLOOKUP(U17,$C$55:$C$176,$J$55:$J$176) -> 46235 | T17: {=SUMPRODUCT(($C$55:$C$175=U17)*(U$54:$AI$54<=TODAY())*(ISNUMBER(U$56:$AI$176)),U$56:$AI$176)} -> 0 | U17: =IFERROR(HYPERLINK(INDEX($D$55:$D$176,MATCH(Q17,$I$55:$I$176,0)),INDEX($C$55:$C$176,MATCH(Q17,$I$55:$I$176,0)) ), "" ) -> 30 - DA000491Z_DE000492Z - STC Scania G_ | Z17: =Q17/$C$5 -> 0.025992932 | AA17: =Z17+AA16 -> 0.691412 | AB17: {=IFERROR(INDEX($T$55:$T$176,MATCH(1,($AP$55:$AP$176=U17)*($S$55:$S$176="Previsto"), 0) ), "")} -> 1 | AC17: {=IFERROR( INDEX($T$55:$T$176,MATCH(1,($AP$55:$AP$176=U17)*($S$55:$S$176="Real"),0)),"")} -> 0.95 | AD17: =IF(OR(AB17="",AC17=""),"",IF(AC17=100%,"CONCLUÍDO",IF(AC17=0,IF(AB17=0,"PROJETO NÃO INICIADO","FALTA DE ACOMPANHAMENTO"),IF(AC17>AB17,"ADIANTADO",IF(AC17=AB17,"CONFORME PLANEJADO","ATRASO"))))) -> ATRASO | AE17: 1 | AS17: =AVERAGE(AS5:AS16) -> 0.4673 | AT17: =AVERAGE(AT5:AT16) -> 0.731075 | AU17: =AT17*AS17 -> 0.34163135
F18: Outros | G18: =SUMIF($B$55:$B$176,F18,$N$55:$N$176) -> 46052 | O18: 13 | P18: =_xlfn.XLOOKUP(U18,$C$55:$C$176,$A$55:$A$176) -> Kaizen - Custo Evitado | Q18: =IFERROR(LARGE($I$55:$I$176,O18)," ") -> 106763.16 | R18: =_xlfn.XLOOKUP(Q18,$I$55:$I$176,$N$55:$N$176) -> 0 | S18: =_xlfn.XLOOKUP(U18,$C$55:$C$176,$J$55:$J$176) -> 46054 | T18: {=SUMPRODUCT(($C$55:$C$175=U18)*(U$54:$AI$54<=TODAY())*(ISNUMBER(U$56:$AI$176)),U$56:$AI$176)} -> 0 | U18: =IFERROR(HYPERLINK(INDEX($D$55:$D$176,MATCH(Q18,$I$55:$I$176,0)),INDEX($C$55:$C$176,MATCH(Q18,$I$55:$I$176,0)) ), "" ) -> 02 - Redução na quantidade de lâmpadas acessa, na produção | Z18: =Q18/$C$5 -> 0.024131197 | AA18: =Z18+AA17 -> 0.7155432 | AB18: {=IFERROR(INDEX($T$55:$T$176,MATCH(1,($AP$55:$AP$176=U18)*($S$55:$S$176="Previsto"), 0) ), "")} -> 1 | AC18: {=IFERROR( INDEX($T$55:$T$176,MATCH(1,($AP$55:$AP$176=U18)*($S$55:$S$176="Real"),0)),"")} -> 1 | AD18: =IF(OR(AB18="",AC18=""),"",IF(AC18=100%,"CONCLUÍDO",IF(AC18=0,IF(AB18=0,"PROJETO NÃO INICIADO","FALTA DE ACOMPANHAMENTO"),IF(AC18>AB18,"ADIANTADO",IF(AC18=AB18,"CONFORME PLANEJADO","ATRASO"))))) -> CONCLUÍDO | AE18: 1
O19: 14 | P19: =_xlfn.XLOOKUP(U19,$C$55:$C$176,$A$55:$A$176) -> BSW | Q19: =IFERROR(LARGE($I$55:$I$176,O19)," ") -> 106000 | R19: =_xlfn.XLOOKUP(Q19,$I$55:$I$176,$N$55:$N$176) -> 99381.26 | S19: =_xlfn.XLOOKUP(U19,$C$55:$C$176,$J$55:$J$176) -> 46136 | T19: {=SUMPRODUCT(($C$55:$C$175=U19)*(U$54:$AI$54<=TODAY())*(ISNUMBER(U$56:$AI$176)),U$56:$AI$176)} -> 76638.27 | U19: =IFERROR(HYPERLINK(INDEX($D$55:$D$176,MATCH(Q19,$I$55:$I$176,0)),INDEX($C$55:$C$176,MATCH(Q19,$I$55:$I$176,0)) ), "" ) -> 45 - Redução de MP GM000409Z | Z19: =Q19/$C$5 -> 0.023958703 | AA19: =Z19+AA18 -> 0.7395019 | AB19: {=IFERROR(INDEX($T$55:$T$176,MATCH(1,($AP$55:$AP$176=U19)*($S$55:$S$176="Previsto"), 0) ), "")} -> 0.88 | AC19: {=IFERROR( INDEX($T$55:$T$176,MATCH(1,($AP$55:$AP$176=U19)*($S$55:$S$176="Real"),0)),"")} -> 1 | AD19: =IF(OR(AB19="",AC19=""),"",IF(AC19=100%,"CONCLUÍDO",IF(AC19=0,IF(AB19=0,"PROJETO NÃO INICIADO","FALTA DE ACOMPANHAMENTO"),IF(AC19>AB19,"ADIANTADO",IF(AC19=AB19,"CONFORME PLANEJADO","ATRASO"))))) -> CONCLUÍDO | AE19: 1
O20: 15 | P20: =_xlfn.XLOOKUP(U20,$C$55:$C$176,$A$55:$A$176) -> Kaizen - Ganho Recorrente | Q20: =IFERROR(LARGE($I$55:$I$176,O20)," ") -> 96000 | R20: =_xlfn.XLOOKUP(Q20,$I$55:$I$176,$N$55:$N$176) -> 43105 | S20: =_xlfn.XLOOKUP(U20,$C$55:$C$176,$J$55:$J$176) -> 46235 | T20: {=SUMPRODUCT(($C$55:$C$175=U20)*(U$54:$AI$54<=TODAY())*(ISNUMBER(U$56:$AI$176)),U$56:$AI$176)} -> 0 | U20: =IFERROR(HYPERLINK(INDEX($D$55:$D$176,MATCH(Q20,$I$55:$I$176,0)),INDEX($C$55:$C$176,MATCH(Q20,$I$55:$I$176,0)) ), "" ) -> 43 - Automação Boomerang | Z20: =Q20/$C$5 -> 0.021698448 | AA20: =Z20+AA19 -> 0.76120035 | AB20: {=IFERROR(INDEX($T$55:$T$176,MATCH(1,($AP$55:$AP$176=U20)*($S$55:$S$176="Previsto"), 0) ), "")} -> 0.3 | AC20: {=IFERROR( INDEX($T$55:$T$176,MATCH(1,($AP$55:$AP$176=U20)*($S$55:$S$176="Real"),0)),"")} -> 0.32 | AD20: =IF(OR(AB20="",AC20=""),"",IF(AC20=100%,"CONCLUÍDO",IF(AC20=0,IF(AB20=0,"PROJETO NÃO INICIADO","FALTA DE ACOMPANHAMENTO"),IF(AC20>AB20,"ADIANTADO",IF(AC20=AB20,"CONFORME PLANEJADO","ATRASO"))))) -> ADIANTADO | AE20: 1
O21: 16 | P21: =_xlfn.XLOOKUP(U21,$C$55:$C$176,$A$55:$A$176) -> BSW | Q21: =IFERROR(LARGE($I$55:$I$176,O21)," ") -> 92500 | R21: =_xlfn.XLOOKUP(Q21,$I$55:$I$176,$N$55:$N$176) -> 153302.58 | S21: =_xlfn.XLOOKUP(U21,$C$55:$C$176,$J$55:$J$176) -> 46174 | T21: {=SUMPRODUCT(($C$55:$C$175=U21)*(U$54:$AI$54<=TODAY())*(ISNUMBER(U$56:$AI$176)),U$56:$AI$176)} -> 0 | U21: =IFERROR(HYPERLINK(INDEX($D$55:$D$176,MATCH(Q21,$I$55:$I$176,0)),INDEX($C$55:$C$176,MATCH(Q21,$I$55:$I$176,0)) ), "" ) -> 50 - Suporte da lanterna MB003681 | Z21: =Q21/$C$5 -> 0.020907359 | AA21: =Z21+AA20 -> 0.78210771 | AB21: {=IFERROR(INDEX($T$55:$T$176,MATCH(1,($AP$55:$AP$176=U21)*($S$55:$S$176="Previsto"), 0) ), "")} -> 0.86 | AC21: {=IFERROR( INDEX($T$55:$T$176,MATCH(1,($AP$55:$AP$176=U21)*($S$55:$S$176="Real"),0)),"")} -> 0.86 | AD21: =IF(OR(AB21="",AC21=""),"",IF(AC21=100%,"CONCLUÍDO",IF(AC21=0,IF(AB21=0,"PROJETO NÃO INICIADO","FALTA DE ACOMPANHAMENTO"),IF(AC21>AB21,"ADIANTADO",IF(AC21=AB21,"CONFORME PLANEJADO","ATRASO"))))) -> CONFORME PLANEJADO | AE21: 1
O22: 17 | P22: =_xlfn.XLOOKUP(U22,$C$55:$C$176,$A$55:$A$176) -> BSW | Q22: =IFERROR(LARGE($I$55:$I$176,O22)," ") -> 91200 | R22: =_xlfn.XLOOKUP(Q22,$I$55:$I$176,$N$55:$N$176) -> 24530.27 | S22: =_xlfn.XLOOKUP(U22,$C$55:$C$176,$J$55:$J$176) -> 46204 | T22: {=SUMPRODUCT(($C$55:$C$175=U22)*(U$54:$AI$54<=TODAY())*(ISNUMBER(U$56:$AI$176)),U$56:$AI$176)} -> 3614.0314 | U22: =IFERROR(HYPERLINK(INDEX($D$55:$D$176,MATCH(Q22,$I$55:$I$176,0)),INDEX($C$55:$C$176,MATCH(Q22,$I$55:$I$176,0)) ), "" ) -> 56 -Redução de Peso Bruto do item SV001141LA / SV001142LA | Z22: =Q22/$C$5 -> 0.020613526 | AA22: =Z22+AA21 -> 0.80272124 | AB22: {=IFERROR(INDEX($T$55:$T$176,MATCH(1,($AP$55:$AP$176=U22)*($S$55:$S$176="Previsto"), 0) ), "")} -> 1 | AC22: {=IFERROR( INDEX($T$55:$T$176,MATCH(1,($AP$55:$AP$176=U22)*($S$55:$S$176="Real"),0)),"")} -> 1 | AD22: =IF(OR(AB22="",AC22=""),"",IF(AC22=100%,"CONCLUÍDO",IF(AC22=0,IF(AB22=0,"PROJETO NÃO INICIADO","FALTA DE ACOMPANHAMENTO"),IF(AC22>AB22,"ADIANTADO",IF(AC22=AB22,"CONFORME PLANEJADO","ATRASO"))))) -> CONCLUÍDO | AE22: 1
O23: 18 | P23: =_xlfn.XLOOKUP(U23,$C$55:$C$176,$A$55:$A$176) -> BSW | Q23: =IFERROR(LARGE($I$55:$I$176,O23)," ") -> 90000 | R23: =_xlfn.XLOOKUP(Q23,$I$55:$I$176,$N$55:$N$176) -> 41632.63 | S23: =_xlfn.XLOOKUP(U23,$C$55:$C$176,$J$55:$J$176) -> 46174 | T23: {=SUMPRODUCT(($C$55:$C$175=U23)*(U$54:$AI$54<=TODAY())*(ISNUMBER(U$56:$AI$176)),U$56:$AI$176)} -> 11219.738 | U23: =IFERROR(HYPERLINK(INDEX($D$55:$D$176,MATCH(Q23,$I$55:$I$176,0)),INDEX($C$55:$C$176,MATCH(Q23,$I$55:$I$176,0)) ), "" ) -> 27 - DA000459AA - STC Volvo_ | Z23: =Q23/$C$5 -> 0.020342295 | AA23: =Z23+AA22 -> 0.82306353 | AB23: {=IFERROR(INDEX($T$55:$T$176,MATCH(1,($AP$55:$AP$176=U23)*($S$55:$S$176="Previsto"), 0) ), "")} -> 1 | AC23: {=IFERROR( INDEX($T$55:$T$176,MATCH(1,($AP$55:$AP$176=U23)*($S$55:$S$176="Real"),0)),"")} -> 1 | AD23: =IF(OR(AB23="",AC23=""),"",IF(AC23=100%,"CONCLUÍDO",IF(AC23=0,IF(AB23=0,"PROJETO NÃO INICIADO","FALTA DE ACOMPANHAMENTO"),IF(AC23>AB23,"ADIANTADO",IF(AC23=AB23,"CONFORME PLANEJADO","ATRASO"))))) -> CONCLUÍDO | AE23: 1
O24: 19 | P24: =_xlfn.XLOOKUP(U24,$C$55:$C$176,$A$55:$A$176) -> Kaizen - Ganho Recorrente | Q24: =IFERROR(LARGE($I$55:$I$176,O24)," ") -> 68000 | R24: =_xlfn.XLOOKUP(Q24,$I$55:$I$176,$N$55:$N$176) -> 56610.76 | S24: =_xlfn.XLOOKUP(U24,$C$55:$C$176,$J$55:$J$176) -> 46082 | T24: {=SUMPRODUCT(($C$55:$C$175=U24)*(U$54:$AI$54<=TODAY())*(ISNUMBER(U$56:$AI$176)),U$56:$AI$176)} -> 25732.163 | U24: =IFERROR(HYPERLINK(INDEX($D$55:$D$176,MATCH(Q24,$I$55:$I$176,0)),INDEX($C$55:$C$176,MATCH(Q24,$I$55:$I$176,0)) ), "" ) -> 05 - Empilhadeira - Diadema | Z24: =Q24/$C$5 -> 0.015369734 | AA24: =Z24+AA23 -> 0.83843326 | AB24: {=IFERROR(INDEX($T$55:$T$176,MATCH(1,($AP$55:$AP$176=U24)*($S$55:$S$176="Previsto"), 0) ), "")} -> 1 | AC24: {=IFERROR( INDEX($T$55:$T$176,MATCH(1,($AP$55:$AP$176=U24)*($S$55:$S$176="Real"),0)),"")} -> 1 | AD24: =IF(OR(AB24="",AC24=""),"",IF(AC24=100%,"CONCLUÍDO",IF(AC24=0,IF(AB24=0,"PROJETO NÃO INICIADO","FALTA DE ACOMPANHAMENTO"),IF(AC24>AB24,"ADIANTADO",IF(AC24=AB24,"CONFORME PLANEJADO","ATRASO"))))) -> CONCLUÍDO | AE24: 1
O25: 20 | P25: =_xlfn.XLOOKUP(U25,$C$55:$C$176,$A$55:$A$176) -> BSW | Q25: =IFERROR(LARGE($I$55:$I$176,O25)," ") -> 64554.69 | R25: =_xlfn.XLOOKUP(Q25,$I$55:$I$176,$N$55:$N$176) -> 41104.57 | S25: =_xlfn.XLOOKUP(U25,$C$55:$C$176,$J$55:$J$176) -> 46082 | T25: {=SUMPRODUCT(($C$55:$C$175=U25)*(U$54:$AI$54<=TODAY())*(ISNUMBER(U$56:$AI$176)),U$56:$AI$176)} -> 23365.017 | U25: =IFERROR( HYPERLINK( INDEX(Diadema!$D$55:$D$176, MATCH(Q25,Diadema!$I$55:$I$176,0) ), INDEX(Diadema!$C$55:$C$176, MATCH(Q25,Diadema!$I$55:$I$176,0) ) ), "" ) -> 41 - Redução de Peso Bruto do item SV001141LA | Z25: =Q25/$C$5 -> 0.014591006 | AA25: =Z25+AA24 -> 0.85302427 | AB25: {=IFERROR(INDEX($T$55:$T$176,MATCH(1,($AP$55:$AP$176=U25)*($S$55:$S$176="Previsto"), 0) ), "")} -> 1 | AC25: {=IFERROR( INDEX($T$55:$T$176,MATCH(1,($AP$55:$AP$176=U25)*($S$55:$S$176="Real"),0)),"")} -> 1 | AD25: =IF(OR(AB25="",AC25=""),"",IF(AC25=100%,"CONCLUÍDO",IF(AC25=0,IF(AB25=0,"PROJETO NÃO INICIADO","FALTA DE ACOMPANHAMENTO"),IF(AC25>AB25,"ADIANTADO",IF(AC25=AB25,"CONFORME PLANEJADO","ATRASO"))))) -> CONCLUÍDO | AE25: 1
O26: Total | Q26: =SUM(Q6:Q25) -> 3774017.9 | R26: =SUM(R6:R25) -> 2338668.1
A27: 1. KPIs ESTRATÉGICOS
A28: CATEGORIA | B28: KPI | C28: UN | D28: Frequência | E28: TIPO | F28: BASELINE 2025 | G28: META 2026 | H28: Jan | I28: P. Ofensor1 | J28: Fev | K28: P. Ofensor2 | L28: Mar | M28: P. Ofensor3 | N28: Abr | O28: P. Ofensor4 | P28: Mai | Q28: P. Ofensor5 | R28: Jun | S28: P. Ofensor6 | T28: Jul | U28: P. Ofensor7 | V28: Ago | W28: P. Ofensor8 | X28: Set | Y28: P. Ofensor9 | Z28: Out | AA28: P. Ofensor10 | AB28: Nov | AC28: P. Ofensor11 | AD28: Dez | AE28: P. Ofensor12
A29: Financeiro | B29: Margem VA | C29: % | D29: Mensal | E29: Maior Melhor ↑ | F29: 0.346 | G29: 0.361 | H29: 0.321 | I29: Matéria Prima | J29: 0.33 | K29: Matéria Prima | L29: 0.326 | M29: Matéria Prima | N29: 0.358 | O29: Matéria Prima | P29: 0.358 | Q29: Matéria Prima | R29: 0.315 | S29: Matéria Prima | T29: 0.29 | AA29: Matéria Prima
A30: Financeiro | B30: Custo de Scrap (Refugo) | C30: % | D30: Mensal | E30: Menor Melhor ↓ | F30: 0.003 | G30: 0.002 | H30: 0.00201 | I30: Rachadura | J30: 0.0065 | K30: Rachadura | L30: 0.0042 | M30: Rachadura | N30: 0.0043 | O30: Rachadura | P30: 0.0028 | Q30: Rachadura | R30: 0.0021 | S30: Rachadura | T30: 0.0034
A31: Operacional | B31: OEE Prensas Grandes (24) | C31: % | D31: Semanal | E31: Maior Melhor ↑ | F31: 0.501 | G31: 0.56 | H31: 0.4843 | I31: Falta de energia | J31: =J33*J34*J35 -> 0.51104832 | K31: Manutenção | L31: =L33*L34*L35 -> 0.66519873 | M31: Manutenção | N31: 0.7202 | O31: Manutenção | P31: 0.6949 | Q31: Manutenção | R31: 0.6828 | S31: Manutenção | T31: 0.6826 | U31: Manutenção | AA31: Manutenção
A32: Operacional | B32: Eficiência de MO Planta | C32: % | D32: Mensal | E32: Maior Melhor ↑ | F32: 0.562 | G32: 0.64 | H32: 0.551 | I32: Falta de energia | J32: 0.561 | K32: Falta de energia | L32: 0.53 | M32: Falta de OP | N32: 0.508 | O32: Falta de OP | P32: 0.523 | Q32: Falta de OP | R32: 0.595 | S32: Falta de OP | T32: 0.615 | U32: Manutenção | AA32: Manutenção
A33: Operacional | B33: Performance Prensas Grandes (24) | C33: % | D33: Semanal | E33: Maior Melhor ↑ | F33: 0.9261 | G33: 0.95 | H33: 0.8992 | I33: Falta de energia | J33: 0.8879 | K33: Manutenção | L33: 0.9508 | M33: Manutenção | N33: 0.9717 | O33: Manutenção | P33: 0.9461 | Q33: Manutenção | R33: 0.9294 | S33: Manutenção | T33: 0.9542 | U33: Manutenção | AA33: Manutenção
A34: Operacional | B34: Qualidade Prensas Grandes (24) | C34: % | D34: Semanal | E34: Maior Melhor ↑ | F34: 0.955 | G34: 0.965 | H34: 0.9995 | I34: Ferramentaria | J34: 0.9996 | K34: Ferramentaria | L34: 0.9996 | M34: Manutenção | N34: 0.9997 | O34: Manutenção | P34: 0.9997 | Q34: Manutenção | R34: 1 | S34: Manutenção | T34: 0.9994 | U34: Manutenção | AA34: Manutenção
A35: Operacional | B35: Disponibilidade Prensas Grandes (24) | C35: % | D35: Semanal | E35: Maior Melhor ↑ | F35: 0.959 | G35: 0.97 | H35: 0.5389 | I35: Ferramentaria | J35: 0.5758 | K35: Ferramentaria | L35: 0.6999 | M35: Manutenção | N35: 0.7414 | O35: Manutenção | P35: 0.7347 | Q35: Manutenção | R35: 73.47 | S35: Manutenção | T35: 0.7158 | U35: Manutenção | AA35: Manutenção
A36: Operacional | B36: MTBF (Manutenção) | C36: h | D36: Mensal | E36: Maior Melhor ↑ | F36: 13:00 | G36: 15:00 | H36: 0.625 | I36: Quebra mecânica | J36: 0.54166667 | K36: Quebra mecânica | L36: 0.875 | M36: Quebra mecânica | N36: 1.5 | O36: Quebra mecânica | P36: 1.5 | Q36: Quebra mecânica | R36: 2.0833333 | S36: Quebra mecânica
A37: Operacional | B37: MTTR (Manutenção) | C37: h | D37: Mensal | E37: Menor Melhor ↓ | F37: 0:33 | G37: 0:30 | H37: 00:15 | I37: Problema com CLP | J37: 0.048611111 | K37: Quebra mecânica | L37: 0.052083333 | M37: Quebra mecânica | N37: 0.031944444 | O37: Quebra mecânica | P37: 0.038888889 | Q37: Quebra mecânica | R37: 0.14375 | S37: Quebra mecânica
A38: Operacional | B38: Horas Extras | C38: Valor | D38: Mensal | E38: Menor Melhor ↓ | F38: 91000 | G38: 73000 | H38: 108458.31 | I38: Manutenção | J38: 81579 | K38: Manutenção | L38: 95964 | M38: Manutenção | N38: 97861 | O38: Manutenção | P38: 96508 | Q38: Manutenção | R38: 205849 | S38: Manutenção | T38: 125874 | AA38: Manutenção
A39: Operacional | B39: Acuracidade Estoque | C39: Valor | D39: Semanal | E39: Menor Melhor ↓ | F39: 458000 | G39: 358737 | H39: 29000 | I39: Apontamento incorreto | J39: 30000 | K39: Apontamento incorreto | L39: 6176 | M39: Apontamento incorreto | N39: 5680 | O39: Mat. sem saldo | P39: 213.12 | Q39: Mat. sem saldo | R39: 0 | S39: Não aplicável | T39: 2757
A40: Qualidade | B40: PPM Interno | C40: ppm | D40: Mensal | E40: Menor Melhor ↓ | F40: - | G40: 900 | H40: 60593 | I40: Rebarba | J40: 57795 | K40: Rebarba | L40: 19052 | M40: Rebarba | N40: 59710 | O40: Rebarba | P40: 60162 | Q40: Rebarba | R40: 32145 | S40: Rebarba | T40: 20426 | U40: Rebarba | AA40: Rebarba
A41: Qualidade | B41: PPM Externo | C41: ppm | D41: Mensal | E41: Menor Melhor ↓ | F41: 3347 | G41: 3000 | H41: 1 | I41: Solda irregular | J41: 476 | K41: Falta de rosca | L41: 80 | M41: Quebra de FIFO | N41: 30 | O41: Falta de componente | P41: 1 | Q41: Dimensional | R41: 0 | S41: Não aplicável | T41: 5 | U41: Falta de operação | AA41: Falta de operação
...

Sheet Jarinu
A1: DASHBOARD EXECUTIVO - UNIDADE JARINU
A2: Gestão Estratégica de Projetos e Redução de Custos | Grupo Delga | 2026
A4: META DA UNIDADE | B4: RETORNO PREVISTO (Anual) | C4: Retorno Validado (Anual) | D4: PREVISTO 2026 | E4: 💰 RETORNO VALIDADO 2026 | G4: 💰 RETORNO REAL | I4: Extra DRE (Até o momento) | J4: % ATINGIMENTO DA META | L4: INICIATIVAS | O4: TOP 20 Raking de Projetos Valorizados
A5: =Parâmetros!E8 -> 5356000 | B5: =SUM(I55:I144) -> 5582548 | C5: =AU53 -> 7824805.1 | D5: =AT53-AT55 -> 3031400.1 | E5: =SUM(N55:N144) -> 2945612.6 | G5: =SUM(E9,E11:E14) -> 463507.45 | I5: =E8+E10 -> 1009000 | J5: =G5/A5 -> 0.086539852 | L5: =SUM(G8:G10) -> 37 | O5: POS | P5: Tipo | Q5: Valor Previsto | R5: Valor Previsto Custos | S5: Retorno Previsto | T5: Retorno Real até hoje | U5: Projetos | Z5: Peso | AA5: Pareto | AB5: % Previsto | AC5: % Real | AD5: Planejado | AE5: % Responsabilidade Delga
A6: 📊 SAVING PREVISTO POR PILAR | F6: 📋 STATUS DAS INICIATIVAS | I6: 🏭 INDICADORES OPERACIONAIS | O6: {=_xlfn.SEQUENCE(20)} -> 1 | P6: =_xlfn.XLOOKUP(U6,$C$55:$C$144,$A$55:$A$144) -> BSW | Q6: =MAX(I55:I144) -> 1063359 | R6: =_xlfn.XLOOKUP(Q6,$I$55:$I$144,$N$55:$N$144) -> 1145830.2 | S6: =_xlfn.XLOOKUP(U6,$C$55:$C$176,$J$55:$J$176) -> 46296 | T6: {=SUMPRODUCT(($C$55:$C$175=U6)*(U$54:$AI$54<=TODAY())*(ISNUMBER(U$56:$AI$176)),U$56:$AI$176)} -> 0 | U6: =IFERROR(HYPERLINK(INDEX($D$55:$D$144,MATCH(Q6,$I$55:$I$144,0)),INDEX($C$55:$C$144,MATCH(Q6,$I$55:$I$144,0)) ), "" ) -> 06 - Redução consumo MTP aplicando tolerância mínima | Z6: =Q6/$D$5 -> 0.35078148 | AA6: =Pareto!E70 -> 0.19047915 | AB6: {=IFERROR(INDEX($T$55:$T$144,MATCH(1,($AP$55:$AP$144=U6)*($S$55:$S$144="Previsto"), 0) ), "")} -> 0.32939189 | AC6: 0.29 | AD6: =IF(OR(AB6="",AC6=""),"",IF(AC6=100%,"CONCLUÍDO",IF(AC6=0,IF(AB6=0,"PROJETO NÃO INICIADO","FALTA DE ACOMPANHAMENTO"),IF(AC6>AB6,"ADIANTADO",IF(AC6=AB6,"CONFORME PLANEJADO","ATRASO"))))) -> ATRASO | AE6: {=_xlfn.XLOOKUP($U$6:$U$24,$C$55:$C$144,$R$55:$R$144)} -> 0.1
A7: Pilar | B7: Qtd. | C7: Saving (R$) | D7: Saving Validado 2026 | E7: Até o Momento | F7: Status | G7: Qtd. | H7: R$ Previsto | I7: Aderência SPD: Unidade | J7: Aderência SPD: Auditado | K7: Análise de Margem (Form 206) | O7: 2 | P7: =_xlfn.XLOOKUP(U7,$C$55:$C$144,$A$55:$A$144) -> Redução de custo | Q7: =IFERROR(LARGE($I$55:$I$144,O7)," ") -> 560000 | R7: =_xlfn.XLOOKUP(Q7,$I$55:$I$144,$N$55:$N$144) -> 0 | S7: =_xlfn.XLOOKUP(U7,$C$55:$C$176,$J$55:$J$176) -> 46388 | T7: {=SUMPRODUCT(($C$55:$C$175=U7)*(U$54:$AI$54<=TODAY())*(ISNUMBER(U$56:$AI$176)),U$56:$AI$176)} -> 0 | U7: =IFERROR(HYPERLINK(INDEX($D$55:$D$144,MATCH(Q7,$I$55:$I$144,0)),INDEX($C$55:$C$144,MATCH(Q7,$I$55:$I$144,0)) ), "" ) -> 01 - Desenvolver célula de solda para soldar porcas | Z7: =Q7/$D$5 -> 0.18473312 | AA7: =Pareto!E71 -> 0.29079177 | AB7: {=IFERROR(INDEX($T$55:$T$144,MATCH(1,($AP$55:$AP$144=U7)*($S$55:$S$144="Previsto"), 0) ), "")} -> 0.79032258 | AC7: {=IFERROR( INDEX($T$55:$T$144,MATCH(1,($AP$55:$AP$144=U7)*($S$55:$S$144="Real"),0)),"")} -> 0.79 | AD7: =IF(OR(AB7="",AC7=""),"",IF(AC7=100%,"CONCLUÍDO",IF(AC7=0,IF(AB7=0,"PROJETO NÃO INICIADO","FALTA DE ACOMPANHAMENTO"),IF(AC7>AB7,"ADIANTADO",IF(AC7=AB7,"CONFORME PLANEJADO","ATRASO"))))) -> ATRASO | AE7: 0.8
